Not Found: /favicon.ico
Not Found: /api/
Not Found: /favicon.ico
Not Found: /actuator/gateway/routes/
Forbidden (CSRF token from POST incorrect.): /home/
Forbidden (CSRF token from POST incorrect.): /home/
Not Found: /sugar_version.json
Not Found: /Telerik.Web.UI.WebResource.axd
Not Found: /js/NewWindow_2_all.js
Not Found: /cgi-bin/config.exp
Not Found: /cgi-bin/authLogin.cgi
Not Found: /cf_scripts/scripts/ajax/ckeditor/ckeditor.js
Not Found: /favicon.ico
Not Found: /media/media/document/SACI_INFO_QTSKz79.jpg
Not Found: /favicon.ico
Not Found: /static/historypage.js
Not Found: /owa/
Not Found: /favicon.ico
Not Found: /identity/
Not Found: /showLogin.cc
Not Found: /zabbix/favicon.ico
Not Found: /WebInterface/
Not Found: /solr/
Not Found: /webfig/
Not Found: /favicon-32x32.png
Not Found: /ext-js/app/common/zld_product_spec.js
Not Found: /admin/
Not Found: /sitecore/shell/sitecore.version.xml
Not Found: /remote/login/
Not Found: /favicon/favicon.ico
Not Found: /console/
Not Found: /api/session/properties/
Not Found: /index.jsp
Not Found: /aspera/faspex/
/root/Erps/erp_environnement/lib/python3.10/site-packages/django/db/models/fields/__init__.py:1595: RuntimeWarning: DateTimeField ConfirmationBl.dateConfirmation received a naive datetime (2024-08-24 13:40:00.079468) while time zone support is active.
  warnings.warn(
Not Found: /robots.txt
Not Found: /cpsess8233649784/scripts12/terminal/
Not Found: /cpsess1984911709/scripts12/terminal/
Not Found: /robots.txt
Not Found: /sitemap.xml
Not Found: /.well-known/security.txt
Not Found: /robots.txt
/root/Erps/erp_environnement/lib/python3.10/site-packages/django/db/models/fields/__init__.py:1595: RuntimeWarning: DateTimeField ConfirmationBl.dateConfirmation received a naive datetime (2024-08-24 15:18:12.646604) while time zone support is active.
  warnings.warn(
Not Found: /.env
Not Found: /.ssh/id_rsa
Not Found: /database.sql
Not Found: /config/database.php
Not Found: /.svn/wc.db
Not Found: /web.config
Not Found: /api/.env
Not Found: /.git/HEAD
Not Found: /dump.sql
Not Found: /.ssh/id_ecdsa
Not Found: /_vti_pvt/service.pwd
Not Found: /.ssh/id_ed25519
Not Found: /.aws/credentials
Not Found: /wp-config.php
Not Found: /.env.production
Not Found: /_vti_pvt/authors.pwd
Not Found: /cloud-config.yml
Not Found: /config.php
Not Found: /docker-compose.yml
Not Found: /config.yaml
Not Found: /backup.tar.gz
Not Found: /backup.sql
Not Found: /wp-admin/setup-config.php
Not Found: /config.yml
Not Found: /_vti_pvt/administrators.pwd
Not Found: /config.xml
Not Found: /backup.zip
Not Found: /config.json
Not Found: /.vscode/sftp.json
Not Found: /etc/ssl/private/server.key
Not Found: /user_secrets.yml
Not Found: /server.key
Not Found: /config/production.json
Not Found: /secrets.json
Not Found: /phpinfo.php
Not Found: /.kube/config
Not Found: /feed/
Not Found: /etc/shadow/
Not Found: /server-status/
Not Found: /cpsess1984911709/scripts7/zone_editor/
Not Found: /cpsess1984911709/scripts/resbind/
Internal Server Error: /get_sales/
Traceback (most recent call last):
  File "/root/Erps/erp_environnement/lib/python3.10/site-packages/django/core/handlers/exception.py", line 55, in inner
    response = get_response(request)
  File "/root/Erps/erp_environnement/lib/python3.10/site-packages/django/core/handlers/base.py", line 197, in _get_response
    response = wrapped_callback(request, *callback_args, **callback_kwargs)
  File "/root/Erps/erpfinal/erp/inventory/views.py", line 75, in get_sales
    store_id = request.session["store"]
  File "/root/Erps/erp_environnement/lib/python3.10/site-packages/django/contrib/sessions/backends/base.py", line 53, in __getitem__
    return self._session[key]
KeyError: 'store'
Internal Server Error: /get_sales/
Traceback (most recent call last):
  File "/root/Erps/erp_environnement/lib/python3.10/site-packages/django/core/handlers/exception.py", line 55, in inner
    response = get_response(request)
  File "/root/Erps/erp_environnement/lib/python3.10/site-packages/django/core/handlers/base.py", line 197, in _get_response
    response = wrapped_callback(request, *callback_args, **callback_kwargs)
  File "/root/Erps/erpfinal/erp/inventory/views.py", line 75, in get_sales
    store_id = request.session["store"]
  File "/root/Erps/erp_environnement/lib/python3.10/site-packages/django/contrib/sessions/backends/base.py", line 53, in __getitem__
    return self._session[key]
KeyError: 'store'
Not Found: /favicon.ico
Not Found: /autodiscover/autodiscover.json
Not Found: /robots.txt
Not Found: /favicon.ico
Not Found: /favicon.ico
/root/Erps/erp_environnement/lib/python3.10/site-packages/django/db/models/fields/__init__.py:1595: RuntimeWarning: DateTimeField ConfirmationBl.dateConfirmation received a naive datetime (2024-08-24 18:59:51.765251) while time zone support is active.
  warnings.warn(
Not Found: /favicon.ico
Not Found: /favicon.ico
/root/Erps/erp_environnement/lib/python3.10/site-packages/django/db/models/fields/__init__.py:1595: RuntimeWarning: DateTimeField BonTransport.date_depart received a naive datetime (2024-08-28 00:00:00) while time zone support is active.
  warnings.warn(
/root/Erps/erp_environnement/lib/python3.10/site-packages/django/db/models/fields/__init__.py:1595: RuntimeWarning: DateTimeField CourseLivraison.dateTimeAffectation received a naive datetime (2024-08-28 14:43:19.159289) while time zone support is active.
  warnings.warn(
/root/Erps/erp_environnement/lib/python3.10/site-packages/django/db/models/fields/__init__.py:1595: RuntimeWarning: DateTimeField CourseLivraison.dateTimeAffectation received a naive datetime (2024-08-28 14:45:34.681156) while time zone support is active.
  warnings.warn(
/root/Erps/erp_environnement/lib/python3.10/site-packages/django/db/models/fields/__init__.py:1595: RuntimeWarning: DateTimeField CourseLivraison.dateTimeAffectation received a naive datetime (2024-08-28 14:47:12.147110) while time zone support is active.
  warnings.warn(
/root/Erps/erp_environnement/lib/python3.10/site-packages/django/db/models/fields/__init__.py:1595: RuntimeWarning: DateTimeField ConfirmationBl.dateConfirmation received a naive datetime (2024-08-28 14:50:04.725827) while time zone support is active.
  warnings.warn(
Internal Server Error: /gestionRh/PageSalarie
Traceback (most recent call last):
  File "/root/Erps/erp_environnement/lib/python3.10/site-packages/django/core/handlers/exception.py", line 55, in inner
    response = get_response(request)
  File "/root/Erps/erp_environnement/lib/python3.10/site-packages/django/core/handlers/base.py", line 197, in _get_response
    response = wrapped_callback(request, *callback_args, **callback_kwargs)
  File "/root/Erps/erp_environnement/lib/python3.10/site-packages/django/views/generic/base.py", line 104, in view
    return self.dispatch(request, *args, **kwargs)
  File "/root/Erps/erp_environnement/lib/python3.10/site-packages/django/utils/decorators.py", line 46, in _wrapper
    return bound_method(*args, **kwargs)
  File "/root/Erps/erp_environnement/lib/python3.10/site-packages/django/contrib/auth/decorators.py", line 23, in _wrapper_view
    return view_func(request, *args, **kwargs)
  File "/root/Erps/erpfinal/erp/gestionRH/views.py", line 1465, in dispatch
    return super().dispatch(*args, **kwargs)
  File "/root/Erps/erp_environnement/lib/python3.10/site-packages/django/contrib/auth/mixins.py", line 73, in dispatch
    return super().dispatch(request, *args, **kwargs)
  File "/root/Erps/erp_environnement/lib/python3.10/site-packages/django/contrib/auth/mixins.py", line 135, in dispatch
    return super().dispatch(request, *args, **kwargs)
  File "/root/Erps/erp_environnement/lib/python3.10/site-packages/django/views/generic/base.py", line 143, in dispatch
    return handler(request, *args, **kwargs)
  File "/root/Erps/erpfinal/erp/gestionRH/views.py", line 1478, in post
    cout_heure = Decimal(dataInvoice.get('coutH', '0'))
decimal.InvalidOperation: [<class 'decimal.ConversionSyntax'>]
Not Found: /.env
/root/Erps/erp_environnement/lib/python3.10/site-packages/django/db/models/fields/__init__.py:1595: RuntimeWarning: DateTimeField ConfirmationBl.dateConfirmation received a naive datetime (2024-08-28 15:38:04.625197) while time zone support is active.
  warnings.warn(
/root/Erps/erp_environnement/lib/python3.10/site-packages/django/db/models/fields/__init__.py:1595: RuntimeWarning: DateTimeField ConfirmationBl.dateConfirmation received a naive datetime (2024-08-28 15:38:05.278267) while time zone support is active.
  warnings.warn(
Internal Server Error: /gestionRh/PageSalarie
Traceback (most recent call last):
  File "/root/Erps/erp_environnement/lib/python3.10/site-packages/django/core/handlers/exception.py", line 55, in inner
    response = get_response(request)
  File "/root/Erps/erp_environnement/lib/python3.10/site-packages/django/core/handlers/base.py", line 197, in _get_response
    response = wrapped_callback(request, *callback_args, **callback_kwargs)
  File "/root/Erps/erp_environnement/lib/python3.10/site-packages/django/views/generic/base.py", line 104, in view
    return self.dispatch(request, *args, **kwargs)
  File "/root/Erps/erp_environnement/lib/python3.10/site-packages/django/utils/decorators.py", line 46, in _wrapper
    return bound_method(*args, **kwargs)
  File "/root/Erps/erp_environnement/lib/python3.10/site-packages/django/contrib/auth/decorators.py", line 23, in _wrapper_view
    return view_func(request, *args, **kwargs)
  File "/root/Erps/erpfinal/erp/gestionRH/views.py", line 1465, in dispatch
    return super().dispatch(*args, **kwargs)
  File "/root/Erps/erp_environnement/lib/python3.10/site-packages/django/contrib/auth/mixins.py", line 73, in dispatch
    return super().dispatch(request, *args, **kwargs)
  File "/root/Erps/erp_environnement/lib/python3.10/site-packages/django/contrib/auth/mixins.py", line 135, in dispatch
    return super().dispatch(request, *args, **kwargs)
  File "/root/Erps/erp_environnement/lib/python3.10/site-packages/django/views/generic/base.py", line 143, in dispatch
    return handler(request, *args, **kwargs)
  File "/root/Erps/erpfinal/erp/gestionRH/views.py", line 1478, in post
    cout_heure = Decimal(dataInvoice.get('coutH', '0'))
decimal.InvalidOperation: [<class 'decimal.ConversionSyntax'>]
/root/Erps/erp_environnement/lib/python3.10/site-packages/django/db/models/fields/__init__.py:1595: RuntimeWarning: DateTimeField Salarie.datenaiss received a naive datetime (2024-08-03 00:00:00) while time zone support is active.
  warnings.warn(
/root/Erps/erp_environnement/lib/python3.10/site-packages/django/db/models/fields/__init__.py:1595: RuntimeWarning: DateTimeField Salarie.datenaiss received a naive datetime (2024-08-03 00:00:00) while time zone support is active.
  warnings.warn(
Internal Server Error: /gestionRh/PageSalarie
Traceback (most recent call last):
  File "/root/Erps/erp_environnement/lib/python3.10/site-packages/django/core/handlers/exception.py", line 55, in inner
    response = get_response(request)
  File "/root/Erps/erp_environnement/lib/python3.10/site-packages/django/core/handlers/base.py", line 197, in _get_response
    response = wrapped_callback(request, *callback_args, **callback_kwargs)
  File "/root/Erps/erp_environnement/lib/python3.10/site-packages/django/views/generic/base.py", line 104, in view
    return self.dispatch(request, *args, **kwargs)
  File "/root/Erps/erp_environnement/lib/python3.10/site-packages/django/utils/decorators.py", line 46, in _wrapper
    return bound_method(*args, **kwargs)
  File "/root/Erps/erp_environnement/lib/python3.10/site-packages/django/contrib/auth/decorators.py", line 23, in _wrapper_view
    return view_func(request, *args, **kwargs)
  File "/root/Erps/erpfinal/erp/gestionRH/views.py", line 1465, in dispatch
    return super().dispatch(*args, **kwargs)
  File "/root/Erps/erp_environnement/lib/python3.10/site-packages/django/contrib/auth/mixins.py", line 73, in dispatch
    return super().dispatch(request, *args, **kwargs)
  File "/root/Erps/erp_environnement/lib/python3.10/site-packages/django/contrib/auth/mixins.py", line 135, in dispatch
    return super().dispatch(request, *args, **kwargs)
  File "/root/Erps/erp_environnement/lib/python3.10/site-packages/django/views/generic/base.py", line 143, in dispatch
    return handler(request, *args, **kwargs)
  File "/root/Erps/erpfinal/erp/gestionRH/views.py", line 1480, in post
    prime_espece = Decimal(dataInvoice.get('salaireEsp', '0'))
decimal.InvalidOperation: [<class 'decimal.ConversionSyntax'>]
/root/Erps/erp_environnement/lib/python3.10/site-packages/django/db/models/fields/__init__.py:1595: RuntimeWarning: DateTimeField Salarie.datenaiss received a naive datetime (2004-02-04 00:00:00) while time zone support is active.
  warnings.warn(
Internal Server Error: /reglements/newReglement
Traceback (most recent call last):
  File "/root/Erps/erp_environnement/lib/python3.10/site-packages/django/db/backends/base/base.py", line 313, in _commit
    return self.connection.commit()
sqlite3.OperationalError: database is locked

The above exception was the direct cause of the following exception:

Traceback (most recent call last):
  File "/root/Erps/erp_environnement/lib/python3.10/site-packages/django/core/handlers/exception.py", line 55, in inner
    response = get_response(request)
  File "/root/Erps/erpfinal/erp/users/middleware.py", line 14, in __call__
    myuser.save()
  File "/root/Erps/erpfinal/erp/users/models.py", line 22, in save
    super(CustomUser, self).save(*args, **kwargs)
  File "/root/Erps/erp_environnement/lib/python3.10/site-packages/django/contrib/auth/base_user.py", line 76, in save
    super().save(*args, **kwargs)
  File "/root/Erps/erp_environnement/lib/python3.10/site-packages/django/db/models/base.py", line 814, in save
    self.save_base(
  File "/root/Erps/erp_environnement/lib/python3.10/site-packages/django/db/models/base.py", line 873, in save_base
    with context_manager:
  File "/root/Erps/erp_environnement/lib/python3.10/site-packages/django/db/transaction.py", line 263, in __exit__
    connection.commit()
  File "/root/Erps/erp_environnement/lib/python3.10/site-packages/django/utils/asyncio.py", line 26, in inner
    return func(*args, **kwargs)
  File "/root/Erps/erp_environnement/lib/python3.10/site-packages/django/db/backends/base/base.py", line 337, in commit
    self._commit()
  File "/root/Erps/erp_environnement/lib/python3.10/site-packages/django/db/backends/base/base.py", line 312, in _commit
    with debug_transaction(self, "COMMIT"), self.wrap_database_errors:
  File "/root/Erps/erp_environnement/lib/python3.10/site-packages/django/db/utils.py", line 91, in __exit__
    raise dj_exc_value.with_traceback(traceback) from exc_value
  File "/root/Erps/erp_environnement/lib/python3.10/site-packages/django/db/backends/base/base.py", line 313, in _commit
    return self.connection.commit()
django.db.utils.OperationalError: database is locked
/root/Erps/erp_environnement/lib/python3.10/site-packages/django/db/models/fields/__init__.py:1595: RuntimeWarning: DateTimeField ConfirmationBl.dateConfirmation received a naive datetime (2024-08-28 15:59:02.230101) while time zone support is active.
  warnings.warn(
Internal Server Error: /static/css/core.css
Traceback (most recent call last):
  File "/root/Erps/erp_environnement/lib/python3.10/site-packages/django/db/backends/base/base.py", line 313, in _commit
    return self.connection.commit()
sqlite3.OperationalError: database is locked

The above exception was the direct cause of the following exception:

Traceback (most recent call last):
  File "/root/Erps/erp_environnement/lib/python3.10/site-packages/django/core/handlers/exception.py", line 55, in inner
    response = get_response(request)
  File "/root/Erps/erpfinal/erp/users/middleware.py", line 14, in __call__
    myuser.save()
  File "/root/Erps/erpfinal/erp/users/models.py", line 22, in save
    super(CustomUser, self).save(*args, **kwargs)
  File "/root/Erps/erp_environnement/lib/python3.10/site-packages/django/contrib/auth/base_user.py", line 76, in save
    super().save(*args, **kwargs)
  File "/root/Erps/erp_environnement/lib/python3.10/site-packages/django/db/models/base.py", line 814, in save
    self.save_base(
  File "/root/Erps/erp_environnement/lib/python3.10/site-packages/django/db/models/base.py", line 873, in save_base
    with context_manager:
  File "/root/Erps/erp_environnement/lib/python3.10/site-packages/django/db/transaction.py", line 263, in __exit__
    connection.commit()
  File "/root/Erps/erp_environnement/lib/python3.10/site-packages/django/utils/asyncio.py", line 26, in inner
    return func(*args, **kwargs)
  File "/root/Erps/erp_environnement/lib/python3.10/site-packages/django/db/backends/base/base.py", line 337, in commit
    self._commit()
  File "/root/Erps/erp_environnement/lib/python3.10/site-packages/django/db/backends/base/base.py", line 312, in _commit
    with debug_transaction(self, "COMMIT"), self.wrap_database_errors:
  File "/root/Erps/erp_environnement/lib/python3.10/site-packages/django/db/utils.py", line 91, in __exit__
    raise dj_exc_value.with_traceback(traceback) from exc_value
  File "/root/Erps/erp_environnement/lib/python3.10/site-packages/django/db/backends/base/base.py", line 313, in _commit
    return self.connection.commit()
django.db.utils.OperationalError: database is locked
Internal Server Error: /get_sales/
Traceback (most recent call last):
  File "/root/Erps/erp_environnement/lib/python3.10/site-packages/django/db/backends/base/base.py", line 313, in _commit
    return self.connection.commit()
sqlite3.OperationalError: database is locked

The above exception was the direct cause of the following exception:

Traceback (most recent call last):
  File "/root/Erps/erp_environnement/lib/python3.10/site-packages/django/core/handlers/exception.py", line 55, in inner
    response = get_response(request)
  File "/root/Erps/erpfinal/erp/users/middleware.py", line 14, in __call__
    myuser.save()
  File "/root/Erps/erpfinal/erp/users/models.py", line 22, in save
    super(CustomUser, self).save(*args, **kwargs)
  File "/root/Erps/erp_environnement/lib/python3.10/site-packages/django/contrib/auth/base_user.py", line 76, in save
    super().save(*args, **kwargs)
  File "/root/Erps/erp_environnement/lib/python3.10/site-packages/django/db/models/base.py", line 814, in save
    self.save_base(
  File "/root/Erps/erp_environnement/lib/python3.10/site-packages/django/db/models/base.py", line 873, in save_base
    with context_manager:
  File "/root/Erps/erp_environnement/lib/python3.10/site-packages/django/db/transaction.py", line 263, in __exit__
    connection.commit()
  File "/root/Erps/erp_environnement/lib/python3.10/site-packages/django/utils/asyncio.py", line 26, in inner
    return func(*args, **kwargs)
  File "/root/Erps/erp_environnement/lib/python3.10/site-packages/django/db/backends/base/base.py", line 337, in commit
    self._commit()
  File "/root/Erps/erp_environnement/lib/python3.10/site-packages/django/db/backends/base/base.py", line 312, in _commit
    with debug_transaction(self, "COMMIT"), self.wrap_database_errors:
  File "/root/Erps/erp_environnement/lib/python3.10/site-packages/django/db/utils.py", line 91, in __exit__
    raise dj_exc_value.with_traceback(traceback) from exc_value
  File "/root/Erps/erp_environnement/lib/python3.10/site-packages/django/db/backends/base/base.py", line 313, in _commit
    return self.connection.commit()
django.db.utils.OperationalError: database is locked
Internal Server Error: /dns-query
Traceback (most recent call last):
  File "/root/Erps/erp_environnement/lib/python3.10/site-packages/django/core/handlers/exception.py", line 55, in inner
    response = get_response(request)
  File "/root/Erps/erp_environnement/lib/python3.10/site-packages/django/utils/deprecation.py", line 136, in __call__
    response = self.process_response(request, response)
  File "/root/Erps/erp_environnement/lib/python3.10/site-packages/django/middleware/common.py", line 108, in process_response
    return self.response_redirect_class(self.get_full_path_with_slash(request))
  File "/root/Erps/erp_environnement/lib/python3.10/site-packages/django/middleware/common.py", line 87, in get_full_path_with_slash
    raise RuntimeError(
RuntimeError: You called this URL via POST, but the URL doesn't end in a slash and you have APPEND_SLASH set. Django can't redirect to the slash URL while maintaining POST data. Change your form to point to 38.242.243.169/dns-query/ (note the trailing slash), or set APPEND_SLASH=False in your Django settings.
Internal Server Error: /dns-query
Traceback (most recent call last):
  File "/root/Erps/erp_environnement/lib/python3.10/site-packages/django/core/handlers/exception.py", line 55, in inner
    response = get_response(request)
  File "/root/Erps/erp_environnement/lib/python3.10/site-packages/django/utils/deprecation.py", line 136, in __call__
    response = self.process_response(request, response)
  File "/root/Erps/erp_environnement/lib/python3.10/site-packages/django/middleware/common.py", line 108, in process_response
    return self.response_redirect_class(self.get_full_path_with_slash(request))
  File "/root/Erps/erp_environnement/lib/python3.10/site-packages/django/middleware/common.py", line 87, in get_full_path_with_slash
    raise RuntimeError(
RuntimeError: You called this URL via POST, but the URL doesn't end in a slash and you have APPEND_SLASH set. Django can't redirect to the slash URL while maintaining POST data. Change your form to point to 38.242.243.169/dns-query/ (note the trailing slash), or set APPEND_SLASH=False in your Django settings.
Internal Server Error: /query
Traceback (most recent call last):
  File "/root/Erps/erp_environnement/lib/python3.10/site-packages/django/core/handlers/exception.py", line 55, in inner
    response = get_response(request)
  File "/root/Erps/erp_environnement/lib/python3.10/site-packages/django/utils/deprecation.py", line 136, in __call__
    response = self.process_response(request, response)
  File "/root/Erps/erp_environnement/lib/python3.10/site-packages/django/middleware/common.py", line 108, in process_response
    return self.response_redirect_class(self.get_full_path_with_slash(request))
  File "/root/Erps/erp_environnement/lib/python3.10/site-packages/django/middleware/common.py", line 87, in get_full_path_with_slash
    raise RuntimeError(
RuntimeError: You called this URL via POST, but the URL doesn't end in a slash and you have APPEND_SLASH set. Django can't redirect to the slash URL while maintaining POST data. Change your form to point to 38.242.243.169/query/ (note the trailing slash), or set APPEND_SLASH=False in your Django settings.
Internal Server Error: /query
Traceback (most recent call last):
  File "/root/Erps/erp_environnement/lib/python3.10/site-packages/django/core/handlers/exception.py", line 55, in inner
    response = get_response(request)
  File "/root/Erps/erp_environnement/lib/python3.10/site-packages/django/utils/deprecation.py", line 136, in __call__
    response = self.process_response(request, response)
  File "/root/Erps/erp_environnement/lib/python3.10/site-packages/django/middleware/common.py", line 108, in process_response
    return self.response_redirect_class(self.get_full_path_with_slash(request))
  File "/root/Erps/erp_environnement/lib/python3.10/site-packages/django/middleware/common.py", line 87, in get_full_path_with_slash
    raise RuntimeError(
RuntimeError: You called this URL via POST, but the URL doesn't end in a slash and you have APPEND_SLASH set. Django can't redirect to the slash URL while maintaining POST data. Change your form to point to 38.242.243.169/query/ (note the trailing slash), or set APPEND_SLASH=False in your Django settings.
Internal Server Error: /resolve
Traceback (most recent call last):
  File "/root/Erps/erp_environnement/lib/python3.10/site-packages/django/core/handlers/exception.py", line 55, in inner
    response = get_response(request)
  File "/root/Erps/erp_environnement/lib/python3.10/site-packages/django/utils/deprecation.py", line 136, in __call__
    response = self.process_response(request, response)
  File "/root/Erps/erp_environnement/lib/python3.10/site-packages/django/middleware/common.py", line 108, in process_response
    return self.response_redirect_class(self.get_full_path_with_slash(request))
  File "/root/Erps/erp_environnement/lib/python3.10/site-packages/django/middleware/common.py", line 87, in get_full_path_with_slash
    raise RuntimeError(
RuntimeError: You called this URL via POST, but the URL doesn't end in a slash and you have APPEND_SLASH set. Django can't redirect to the slash URL while maintaining POST data. Change your form to point to 38.242.243.169/resolve/ (note the trailing slash), or set APPEND_SLASH=False in your Django settings.
Internal Server Error: /resolve
Traceback (most recent call last):
  File "/root/Erps/erp_environnement/lib/python3.10/site-packages/django/core/handlers/exception.py", line 55, in inner
    response = get_response(request)
  File "/root/Erps/erp_environnement/lib/python3.10/site-packages/django/utils/deprecation.py", line 136, in __call__
    response = self.process_response(request, response)
  File "/root/Erps/erp_environnement/lib/python3.10/site-packages/django/middleware/common.py", line 108, in process_response
    return self.response_redirect_class(self.get_full_path_with_slash(request))
  File "/root/Erps/erp_environnement/lib/python3.10/site-packages/django/middleware/common.py", line 87, in get_full_path_with_slash
    raise RuntimeError(
RuntimeError: You called this URL via POST, but the URL doesn't end in a slash and you have APPEND_SLASH set. Django can't redirect to the slash URL while maintaining POST data. Change your form to point to 38.242.243.169/resolve/ (note the trailing slash), or set APPEND_SLASH=False in your Django settings.
Forbidden (Referer checking failed - no Referer.): /
Forbidden (Referer checking failed - no Referer.): /
Not Found: /robots.txt
Not Found: /.env
Not Found: /.env
Not Found: /hello.world
Not Found: /vendor/phpunit/phpunit/src/Util/PHP/eval-stdin.php
Not Found: /vendor/phpunit/phpunit/Util/PHP/eval-stdin.php
Not Found: /vendor/phpunit/src/Util/PHP/eval-stdin.php
Not Found: /vendor/phpunit/Util/PHP/eval-stdin.php
Not Found: /vendor/phpunit/phpunit/LICENSE/eval-stdin.php
Not Found: /vendor/vendor/phpunit/phpunit/src/Util/PHP/eval-stdin.php
Not Found: /phpunit/phpunit/src/Util/PHP/eval-stdin.php
Not Found: /phpunit/phpunit/Util/PHP/eval-stdin.php
Not Found: /phpunit/src/Util/PHP/eval-stdin.php
Not Found: /phpunit/Util/PHP/eval-stdin.php
Not Found: /lib/phpunit/phpunit/src/Util/PHP/eval-stdin.php
Not Found: /lib/phpunit/phpunit/Util/PHP/eval-stdin.php
Not Found: /lib/phpunit/src/Util/PHP/eval-stdin.php
Not Found: /lib/phpunit/Util/PHP/eval-stdin.php
Not Found: /lib/vendor/phpunit/phpunit/src/Util/PHP/eval-stdin.php
Not Found: /laravel/vendor/phpunit/phpunit/src/Util/PHP/eval-stdin.php
Not Found: /www/vendor/phpunit/phpunit/src/Util/PHP/eval-stdin.php
Not Found: /ws/vendor/phpunit/phpunit/src/Util/PHP/eval-stdin.php
Not Found: /yii/vendor/phpunit/phpunit/src/Util/PHP/eval-stdin.php
Not Found: /zend/vendor/phpunit/phpunit/src/Util/PHP/eval-stdin.php
Not Found: /ws/ec/vendor/phpunit/phpunit/src/Util/PHP/eval-stdin.php
Not Found: /V2/vendor/phpunit/phpunit/src/Util/PHP/eval-stdin.php
Not Found: /tests/vendor/phpunit/phpunit/src/Util/PHP/eval-stdin.php
Not Found: /test/vendor/phpunit/phpunit/src/Util/PHP/eval-stdin.php
Not Found: /testing/vendor/phpunit/phpunit/src/Util/PHP/eval-stdin.php
Not Found: /api/vendor/phpunit/phpunit/src/Util/PHP/eval-stdin.php
Not Found: /demo/vendor/phpunit/phpunit/src/Util/PHP/eval-stdin.php
Not Found: /cms/vendor/phpunit/phpunit/src/Util/PHP/eval-stdin.php
Not Found: /crm/vendor/phpunit/phpunit/src/Util/PHP/eval-stdin.php
Not Found: /admin/vendor/phpunit/phpunit/src/Util/PHP/eval-stdin.php
Not Found: /backup/vendor/phpunit/phpunit/src/Util/PHP/eval-stdin.php
Not Found: /blog/vendor/phpunit/phpunit/src/Util/PHP/eval-stdin.php
Not Found: /workspace/drupal/vendor/phpunit/phpunit/src/Util/PHP/eval-stdin.php
Not Found: /panel/vendor/phpunit/phpunit/src/Util/PHP/eval-stdin.php
Not Found: /public/vendor/phpunit/phpunit/src/Util/PHP/eval-stdin.php
Not Found: /apps/vendor/phpunit/phpunit/src/Util/PHP/eval-stdin.php
Not Found: /app/vendor/phpunit/phpunit/src/Util/PHP/eval-stdin.php
Not Found: /index.php
Not Found: /public/index.php
Not Found: /index.php
Not Found: /index.php
Not Found: /RDWeb/Pages/
/root/Erps/erp_environnement/lib/python3.10/site-packages/django/db/models/fields/__init__.py:1595: RuntimeWarning: DateTimeField ConfirmationBl.dateConfirmation received a naive datetime (2024-08-28 21:12:17.580639) while time zone support is active.
  warnings.warn(
/root/Erps/erp_environnement/lib/python3.10/site-packages/django/db/models/fields/__init__.py:1595: RuntimeWarning: DateTimeField ConfirmationBl.dateConfirmation received a naive datetime (2024-08-28 21:13:51.361213) while time zone support is active.
  warnings.warn(
Not Found: /RDWeb/Pages/
/root/Erps/erp_environnement/lib/python3.10/site-packages/django/db/models/fields/__init__.py:1595: RuntimeWarning: DateTimeField ConfirmationBl.dateConfirmation received a naive datetime (2024-08-28 21:17:28.297434) while time zone support is active.
  warnings.warn(
Not Found: /robots.txt
Not Found: /robots.txt
Not Found: /internal_forms_authentication/
Not Found: /robots.txt
Not Found: /robots.txt
Not Found: /actuator/gateway/routes/
Not Found: /robots.txt
Not Found: /remote/login/
Not Found: /login/
Not Found: /webui/
Not Found: /favicon.ico
Not Found: /robots.txt
Not Found: /autodiscover/autodiscover.json
Not Found: /geoserver/web/
Not Found: /.git/config
Not Found: /robots.txt
Not Found: /.DS_Store
Not Found: /.git/config
Not Found: /robots.txt
Not Found: /static/favicon.ico
Not Found: /robots.txt
Not Found: /robots.txt
Not Found: /sitemap.xml
Not Found: /config.json
Not Found: /robots.txt
Not Found: /sitemap.xml
Not Found: /robots.txt
Not Found: /cpsess8138755743/scripts12/terminal/
/root/Erps/erp_environnement/lib/python3.10/site-packages/django/db/models/fields/__init__.py:1595: RuntimeWarning: DateTimeField ConfirmationBl.dateConfirmation received a naive datetime (2024-08-29 08:27:30.053577) while time zone support is active.
  warnings.warn(
Internal Server Error: /ajax
Traceback (most recent call last):
  File "/root/Erps/erp_environnement/lib/python3.10/site-packages/django/core/handlers/exception.py", line 55, in inner
    response = get_response(request)
  File "/root/Erps/erp_environnement/lib/python3.10/site-packages/django/utils/deprecation.py", line 136, in __call__
    response = self.process_response(request, response)
  File "/root/Erps/erp_environnement/lib/python3.10/site-packages/django/middleware/common.py", line 108, in process_response
    return self.response_redirect_class(self.get_full_path_with_slash(request))
  File "/root/Erps/erp_environnement/lib/python3.10/site-packages/django/middleware/common.py", line 87, in get_full_path_with_slash
    raise RuntimeError(
RuntimeError: You called this URL via POST, but the URL doesn't end in a slash and you have APPEND_SLASH set. Django can't redirect to the slash URL while maintaining POST data. Change your form to point to 38.242.243.169/ajax/ (note the trailing slash), or set APPEND_SLASH=False in your Django settings.
Not Found: /.git/config
/root/Erps/erp_environnement/lib/python3.10/site-packages/django/db/models/fields/__init__.py:1595: RuntimeWarning: DateTimeField ConfirmationBl.dateConfirmation received a naive datetime (2024-08-29 08:48:53.917249) while time zone support is active.
  warnings.warn(
Internal Server Error: /ventes/new-sell-diva
Traceback (most recent call last):
  File "/root/Erps/erp_environnement/lib/python3.10/site-packages/django/db/backends/base/base.py", line 313, in _commit
    return self.connection.commit()
sqlite3.OperationalError: database is locked

The above exception was the direct cause of the following exception:

Traceback (most recent call last):
  File "/root/Erps/erp_environnement/lib/python3.10/site-packages/django/core/handlers/exception.py", line 55, in inner
    response = get_response(request)
  File "/root/Erps/erpfinal/erp/users/middleware.py", line 14, in __call__
    myuser.save()
  File "/root/Erps/erpfinal/erp/users/models.py", line 22, in save
    super(CustomUser, self).save(*args, **kwargs)
  File "/root/Erps/erp_environnement/lib/python3.10/site-packages/django/contrib/auth/base_user.py", line 76, in save
    super().save(*args, **kwargs)
  File "/root/Erps/erp_environnement/lib/python3.10/site-packages/django/db/models/base.py", line 814, in save
    self.save_base(
  File "/root/Erps/erp_environnement/lib/python3.10/site-packages/django/db/models/base.py", line 873, in save_base
    with context_manager:
  File "/root/Erps/erp_environnement/lib/python3.10/site-packages/django/db/transaction.py", line 263, in __exit__
    connection.commit()
  File "/root/Erps/erp_environnement/lib/python3.10/site-packages/django/utils/asyncio.py", line 26, in inner
    return func(*args, **kwargs)
  File "/root/Erps/erp_environnement/lib/python3.10/site-packages/django/db/backends/base/base.py", line 337, in commit
    self._commit()
  File "/root/Erps/erp_environnement/lib/python3.10/site-packages/django/db/backends/base/base.py", line 312, in _commit
    with debug_transaction(self, "COMMIT"), self.wrap_database_errors:
  File "/root/Erps/erp_environnement/lib/python3.10/site-packages/django/db/utils.py", line 91, in __exit__
    raise dj_exc_value.with_traceback(traceback) from exc_value
  File "/root/Erps/erp_environnement/lib/python3.10/site-packages/django/db/backends/base/base.py", line 313, in _commit
    return self.connection.commit()
django.db.utils.OperationalError: database is locked
Not Found: /favicon.ico
Not Found: /robots.txt
Not Found: /sitemap.txt
/root/Erps/erp_environnement/lib/python3.10/site-packages/django/db/models/fields/__init__.py:1595: RuntimeWarning: DateTimeField ConfirmationBl.dateConfirmation received a naive datetime (2024-08-29 09:07:07.163592) while time zone support is active.
  warnings.warn(
Not Found: /remote/login/
Not Found: /global-protect/login.esp
Not Found: /+CSCOE+/logon.html
/root/Erps/erp_environnement/lib/python3.10/site-packages/django/db/models/fields/__init__.py:1595: RuntimeWarning: DateTimeField ConfirmationBl.dateConfirmation received a naive datetime (2024-08-29 09:20:58.554979) while time zone support is active.
  warnings.warn(
Not Found: /robots.txt
Not Found: /sitemap.txt
/root/Erps/erp_environnement/lib/python3.10/site-packages/django/db/models/fields/__init__.py:1595: RuntimeWarning: DateTimeField BonTransport.date_depart received a naive datetime (2024-08-29 00:00:00) while time zone support is active.
  warnings.warn(
/root/Erps/erp_environnement/lib/python3.10/site-packages/django/db/models/fields/__init__.py:1595: RuntimeWarning: DateTimeField CourseLivraison.dateTimeAffectation received a naive datetime (2024-08-29 09:43:21.441860) while time zone support is active.
  warnings.warn(
/root/Erps/erp_environnement/lib/python3.10/site-packages/django/db/models/fields/__init__.py:1595: RuntimeWarning: DateTimeField CourseLivraison.dateTimeAffectation received a naive datetime (2024-08-29 09:44:12.969601) while time zone support is active.
  warnings.warn(
Requested Range Not Satisfiable: /static/media/ERPLOGO.png
/root/Erps/erp_environnement/lib/python3.10/site-packages/django/db/models/fields/__init__.py:1595: RuntimeWarning: DateTimeField BonTransport.date_depart received a naive datetime (2024-08-29 00:00:00) while time zone support is active.
  warnings.warn(
/root/Erps/erp_environnement/lib/python3.10/site-packages/django/db/models/fields/__init__.py:1595: RuntimeWarning: DateTimeField BonTransport.date_depart received a naive datetime (2024-08-29 00:00:00) while time zone support is active.
  warnings.warn(
Requested Range Not Satisfiable: /static/media/ERPLOGO.png
/root/Erps/erp_environnement/lib/python3.10/site-packages/django/db/models/fields/__init__.py:1595: RuntimeWarning: DateTimeField CourseLivraison.dateTimeAffectation received a naive datetime (2024-08-29 09:45:21.862753) while time zone support is active.
  warnings.warn(
/root/Erps/erp_environnement/lib/python3.10/site-packages/django/db/models/fields/__init__.py:1595: RuntimeWarning: DateTimeField CourseLivraison.dateTimeAffectation received a naive datetime (2024-08-29 09:46:36.884027) while time zone support is active.
  warnings.warn(
/root/Erps/erp_environnement/lib/python3.10/site-packages/django/db/models/fields/__init__.py:1595: RuntimeWarning: DateTimeField CourseLivraison.dateTimeAffectation received a naive datetime (2024-08-29 09:48:12.231893) while time zone support is active.
  warnings.warn(
/root/Erps/erp_environnement/lib/python3.10/site-packages/django/db/models/fields/__init__.py:1595: RuntimeWarning: DateTimeField ConfirmationBl.dateConfirmation received a naive datetime (2024-08-29 10:18:58.441403) while time zone support is active.
  warnings.warn(
Requested Range Not Satisfiable: /static/media/BG2.webp
/root/Erps/erp_environnement/lib/python3.10/site-packages/django/db/models/fields/__init__.py:1595: RuntimeWarning: DateTimeField Tentatives.dateDebutTentative received a naive datetime (2024-08-29 00:00:00) while time zone support is active.
  warnings.warn(
/root/Erps/erp_environnement/lib/python3.10/site-packages/django/db/models/fields/__init__.py:1595: RuntimeWarning: DateTimeField Tentatives.dateFinTentative received a naive datetime (2024-08-29 00:00:00) while time zone support is active.
  warnings.warn(
Not Found: /.env
Forbidden (Referer checking failed - no Referer.): /
Not Found: /cpsess8138755743/scripts12/terminal/
Requested Range Not Satisfiable: /static/media/ERPLOGO.png
Not Found: /robots.txt
Not Found: /robots.txt
Not Found: /RDWeb/Pages/
/root/Erps/erp_environnement/lib/python3.10/site-packages/django/db/models/fields/__init__.py:1595: RuntimeWarning: DateTimeField ConfirmationBl.dateConfirmation received a naive datetime (2024-08-29 10:49:33.136424) while time zone support is active.
  warnings.warn(
Not Found: /cpsess8138755743/scripts12/terminal/
Not Found: /.vscode/sftp.json
/root/Erps/erp_environnement/lib/python3.10/site-packages/django/db/models/fields/__init__.py:1595: RuntimeWarning: DateTimeField ConfirmationBl.dateConfirmation received a naive datetime (2024-08-29 11:32:22.809834) while time zone support is active.
  warnings.warn(
Not Found: /cgi-bin/supervisor/Factory.cgi
Not Found: /robots.txt
Not Found: /robots.txt
Not Found: /cpsess8138755743/scripts12/terminal/
Requested Range Not Satisfiable: /static/media/ERPLOGO.png
Not Found: /remote/login/
Not Found: /login/
Not Found: /ab2g/
Not Found: /ab2h/
Not Found: /alive.php
Not Found: /favicon.ico
Not Found: /cpsess8138755743/scripts12/terminal/
Internal Server Error: /static/js/core.js
Traceback (most recent call last):
  File "/root/Erps/erp_environnement/lib/python3.10/site-packages/django/db/backends/base/base.py", line 313, in _commit
    return self.connection.commit()
sqlite3.OperationalError: database is locked

The above exception was the direct cause of the following exception:

Traceback (most recent call last):
  File "/root/Erps/erp_environnement/lib/python3.10/site-packages/django/core/handlers/exception.py", line 55, in inner
    response = get_response(request)
  File "/root/Erps/erpfinal/erp/users/middleware.py", line 14, in __call__
    myuser.save()
  File "/root/Erps/erpfinal/erp/users/models.py", line 22, in save
    super(CustomUser, self).save(*args, **kwargs)
  File "/root/Erps/erp_environnement/lib/python3.10/site-packages/django/contrib/auth/base_user.py", line 76, in save
    super().save(*args, **kwargs)
  File "/root/Erps/erp_environnement/lib/python3.10/site-packages/django/db/models/base.py", line 814, in save
    self.save_base(
  File "/root/Erps/erp_environnement/lib/python3.10/site-packages/django/db/models/base.py", line 873, in save_base
    with context_manager:
  File "/root/Erps/erp_environnement/lib/python3.10/site-packages/django/db/transaction.py", line 263, in __exit__
    connection.commit()
  File "/root/Erps/erp_environnement/lib/python3.10/site-packages/django/utils/asyncio.py", line 26, in inner
    return func(*args, **kwargs)
  File "/root/Erps/erp_environnement/lib/python3.10/site-packages/django/db/backends/base/base.py", line 337, in commit
    self._commit()
  File "/root/Erps/erp_environnement/lib/python3.10/site-packages/django/db/backends/base/base.py", line 312, in _commit
    with debug_transaction(self, "COMMIT"), self.wrap_database_errors:
  File "/root/Erps/erp_environnement/lib/python3.10/site-packages/django/db/utils.py", line 91, in __exit__
    raise dj_exc_value.with_traceback(traceback) from exc_value
  File "/root/Erps/erp_environnement/lib/python3.10/site-packages/django/db/backends/base/base.py", line 313, in _commit
    return self.connection.commit()
django.db.utils.OperationalError: database is locked
Internal Server Error: /stock/new-transfert
Traceback (most recent call last):
  File "/root/Erps/erp_environnement/lib/python3.10/site-packages/django/db/backends/base/base.py", line 313, in _commit
    return self.connection.commit()
sqlite3.OperationalError: database is locked

The above exception was the direct cause of the following exception:

Traceback (most recent call last):
  File "/root/Erps/erp_environnement/lib/python3.10/site-packages/django/core/handlers/exception.py", line 55, in inner
    response = get_response(request)
  File "/root/Erps/erpfinal/erp/users/middleware.py", line 14, in __call__
    myuser.save()
  File "/root/Erps/erpfinal/erp/users/models.py", line 22, in save
    super(CustomUser, self).save(*args, **kwargs)
  File "/root/Erps/erp_environnement/lib/python3.10/site-packages/django/contrib/auth/base_user.py", line 76, in save
    super().save(*args, **kwargs)
  File "/root/Erps/erp_environnement/lib/python3.10/site-packages/django/db/models/base.py", line 814, in save
    self.save_base(
  File "/root/Erps/erp_environnement/lib/python3.10/site-packages/django/db/models/base.py", line 873, in save_base
    with context_manager:
  File "/root/Erps/erp_environnement/lib/python3.10/site-packages/django/db/transaction.py", line 263, in __exit__
    connection.commit()
  File "/root/Erps/erp_environnement/lib/python3.10/site-packages/django/utils/asyncio.py", line 26, in inner
    return func(*args, **kwargs)
  File "/root/Erps/erp_environnement/lib/python3.10/site-packages/django/db/backends/base/base.py", line 337, in commit
    self._commit()
  File "/root/Erps/erp_environnement/lib/python3.10/site-packages/django/db/backends/base/base.py", line 312, in _commit
    with debug_transaction(self, "COMMIT"), self.wrap_database_errors:
  File "/root/Erps/erp_environnement/lib/python3.10/site-packages/django/db/utils.py", line 91, in __exit__
    raise dj_exc_value.with_traceback(traceback) from exc_value
  File "/root/Erps/erp_environnement/lib/python3.10/site-packages/django/db/backends/base/base.py", line 313, in _commit
    return self.connection.commit()
django.db.utils.OperationalError: database is locked
Internal Server Error: /get_sales/
Traceback (most recent call last):
  File "/root/Erps/erp_environnement/lib/python3.10/site-packages/django/db/backends/utils.py", line 89, in _execute
    return self.cursor.execute(sql, params)
  File "/root/Erps/erp_environnement/lib/python3.10/site-packages/django/db/backends/sqlite3/base.py", line 328, in execute
    return super().execute(query, params)
sqlite3.OperationalError: database is locked

The above exception was the direct cause of the following exception:

Traceback (most recent call last):
  File "/root/Erps/erp_environnement/lib/python3.10/site-packages/django/core/handlers/exception.py", line 55, in inner
    response = get_response(request)
  File "/root/Erps/erp_environnement/lib/python3.10/site-packages/django/core/handlers/base.py", line 197, in _get_response
    response = wrapped_callback(request, *callback_args, **callback_kwargs)
  File "/root/Erps/erpfinal/erp/inventory/views.py", line 101, in get_sales
    if len(bill.bon_garantie.all()) == 0 and len(bill.MesbonRetours.all()) == 0 and len(bill.produits_en_bon_sorties.all()) > 0:
  File "/root/Erps/erp_environnement/lib/python3.10/site-packages/django/db/models/query.py", line 380, in __len__
    self._fetch_all()
  File "/root/Erps/erp_environnement/lib/python3.10/site-packages/django/db/models/query.py", line 1881, in _fetch_all
    self._result_cache = list(self._iterable_class(self))
  File "/root/Erps/erp_environnement/lib/python3.10/site-packages/django/db/models/query.py", line 91, in __iter__
    results = compiler.execute_sql(
  File "/root/Erps/erp_environnement/lib/python3.10/site-packages/django/db/models/sql/compiler.py", line 1562, in execute_sql
    cursor.execute(sql, params)
  File "/root/Erps/erp_environnement/lib/python3.10/site-packages/django/db/backends/utils.py", line 102, in execute
    return super().execute(sql, params)
  File "/root/Erps/erp_environnement/lib/python3.10/site-packages/django/db/backends/utils.py", line 67, in execute
    return self._execute_with_wrappers(
  File "/root/Erps/erp_environnement/lib/python3.10/site-packages/django/db/backends/utils.py", line 80, in _execute_with_wrappers
    return executor(sql, params, many, context)
  File "/root/Erps/erp_environnement/lib/python3.10/site-packages/django/db/backends/utils.py", line 84, in _execute
    with self.db.wrap_database_errors:
  File "/root/Erps/erp_environnement/lib/python3.10/site-packages/django/db/utils.py", line 91, in __exit__
    raise dj_exc_value.with_traceback(traceback) from exc_value
  File "/root/Erps/erp_environnement/lib/python3.10/site-packages/django/db/backends/utils.py", line 89, in _execute
    return self.cursor.execute(sql, params)
  File "/root/Erps/erp_environnement/lib/python3.10/site-packages/django/db/backends/sqlite3/base.py", line 328, in execute
    return super().execute(query, params)
django.db.utils.OperationalError: database is locked
Not Found: /favicon.ico
Internal Server Error: /
Traceback (most recent call last):
  File "/root/Erps/erp_environnement/lib/python3.10/site-packages/django/db/backends/base/base.py", line 313, in _commit
    return self.connection.commit()
sqlite3.OperationalError: database is locked

The above exception was the direct cause of the following exception:

Traceback (most recent call last):
  File "/root/Erps/erp_environnement/lib/python3.10/site-packages/django/core/handlers/exception.py", line 55, in inner
    response = get_response(request)
  File "/root/Erps/erpfinal/erp/users/middleware.py", line 14, in __call__
    myuser.save()
  File "/root/Erps/erpfinal/erp/users/models.py", line 22, in save
    super(CustomUser, self).save(*args, **kwargs)
  File "/root/Erps/erp_environnement/lib/python3.10/site-packages/django/contrib/auth/base_user.py", line 76, in save
    super().save(*args, **kwargs)
  File "/root/Erps/erp_environnement/lib/python3.10/site-packages/django/db/models/base.py", line 814, in save
    self.save_base(
  File "/root/Erps/erp_environnement/lib/python3.10/site-packages/django/db/models/base.py", line 873, in save_base
    with context_manager:
  File "/root/Erps/erp_environnement/lib/python3.10/site-packages/django/db/transaction.py", line 263, in __exit__
    connection.commit()
  File "/root/Erps/erp_environnement/lib/python3.10/site-packages/django/utils/asyncio.py", line 26, in inner
    return func(*args, **kwargs)
  File "/root/Erps/erp_environnement/lib/python3.10/site-packages/django/db/backends/base/base.py", line 337, in commit
    self._commit()
  File "/root/Erps/erp_environnement/lib/python3.10/site-packages/django/db/backends/base/base.py", line 312, in _commit
    with debug_transaction(self, "COMMIT"), self.wrap_database_errors:
  File "/root/Erps/erp_environnement/lib/python3.10/site-packages/django/db/utils.py", line 91, in __exit__
    raise dj_exc_value.with_traceback(traceback) from exc_value
  File "/root/Erps/erp_environnement/lib/python3.10/site-packages/django/db/backends/base/base.py", line 313, in _commit
    return self.connection.commit()
django.db.utils.OperationalError: database is locked
Not Found: /favicon.ico
Internal Server Error: /verify-password-validation/
Traceback (most recent call last):
  File "/root/Erps/erp_environnement/lib/python3.10/site-packages/django/db/backends/base/base.py", line 313, in _commit
    return self.connection.commit()
sqlite3.OperationalError: database is locked

The above exception was the direct cause of the following exception:

Traceback (most recent call last):
  File "/root/Erps/erp_environnement/lib/python3.10/site-packages/django/core/handlers/exception.py", line 55, in inner
    response = get_response(request)
  File "/root/Erps/erp_environnement/lib/python3.10/site-packages/django/core/handlers/base.py", line 197, in _get_response
    response = wrapped_callback(request, *callback_args, **callback_kwargs)
  File "/root/Erps/erpfinal/erp/inventory/views.py", line 607, in verifyPassword
    with transaction.atomic():
  File "/root/Erps/erp_environnement/lib/python3.10/site-packages/django/db/transaction.py", line 263, in __exit__
    connection.commit()
  File "/root/Erps/erp_environnement/lib/python3.10/site-packages/django/utils/asyncio.py", line 26, in inner
    return func(*args, **kwargs)
  File "/root/Erps/erp_environnement/lib/python3.10/site-packages/django/db/backends/base/base.py", line 337, in commit
    self._commit()
  File "/root/Erps/erp_environnement/lib/python3.10/site-packages/django/db/backends/base/base.py", line 312, in _commit
    with debug_transaction(self, "COMMIT"), self.wrap_database_errors:
  File "/root/Erps/erp_environnement/lib/python3.10/site-packages/django/db/utils.py", line 91, in __exit__
    raise dj_exc_value.with_traceback(traceback) from exc_value
  File "/root/Erps/erp_environnement/lib/python3.10/site-packages/django/db/backends/base/base.py", line 313, in _commit
    return self.connection.commit()
django.db.utils.OperationalError: database is locked
Forbidden (CSRF token from POST incorrect.): /ventes/confirmBill
Internal Server Error: /ventes/sell-bills
Traceback (most recent call last):
  File "/root/Erps/erp_environnement/lib/python3.10/site-packages/django/template/base.py", line 880, in _resolve_lookup
    current = current[bit]
TypeError: 'Client' object is not subscriptable

During handling of the above exception, another exception occurred:

Traceback (most recent call last):
  File "/root/Erps/erp_environnement/lib/python3.10/site-packages/django/db/backends/utils.py", line 89, in _execute
    return self.cursor.execute(sql, params)
  File "/root/Erps/erp_environnement/lib/python3.10/site-packages/django/db/backends/sqlite3/base.py", line 328, in execute
    return super().execute(query, params)
sqlite3.OperationalError: database is locked

The above exception was the direct cause of the following exception:

Traceback (most recent call last):
  File "/root/Erps/erp_environnement/lib/python3.10/site-packages/django/core/handlers/exception.py", line 55, in inner
    response = get_response(request)
  File "/root/Erps/erp_environnement/lib/python3.10/site-packages/django/core/handlers/base.py", line 220, in _get_response
    response = response.render()
  File "/root/Erps/erp_environnement/lib/python3.10/site-packages/django/template/response.py", line 114, in render
    self.content = self.rendered_content
  File "/root/Erps/erp_environnement/lib/python3.10/site-packages/django/template/response.py", line 92, in rendered_content
    return template.render(context, self._request)
  File "/root/Erps/erp_environnement/lib/python3.10/site-packages/django/template/backends/django.py", line 61, in render
    return self.template.render(context)
  File "/root/Erps/erp_environnement/lib/python3.10/site-packages/django/template/base.py", line 175, in render
    return self._render(context)
  File "/root/Erps/erp_environnement/lib/python3.10/site-packages/django/template/base.py", line 167, in _render
    return self.nodelist.render(context)
  File "/root/Erps/erp_environnement/lib/python3.10/site-packages/django/template/base.py", line 1005, in render
    return SafeString("".join([node.render_annotated(context) for node in self]))
  File "/root/Erps/erp_environnement/lib/python3.10/site-packages/django/template/base.py", line 1005, in <listcomp>
    return SafeString("".join([node.render_annotated(context) for node in self]))
  File "/root/Erps/erp_environnement/lib/python3.10/site-packages/django/template/base.py", line 966, in render_annotated
    return self.render(context)
  File "/root/Erps/erp_environnement/lib/python3.10/site-packages/django/template/loader_tags.py", line 157, in render
    return compiled_parent._render(context)
  File "/root/Erps/erp_environnement/lib/python3.10/site-packages/django/template/base.py", line 167, in _render
    return self.nodelist.render(context)
  File "/root/Erps/erp_environnement/lib/python3.10/site-packages/django/template/base.py", line 1005, in render
    return SafeString("".join([node.render_annotated(context) for node in self]))
  File "/root/Erps/erp_environnement/lib/python3.10/site-packages/django/template/base.py", line 1005, in <listcomp>
    return SafeString("".join([node.render_annotated(context) for node in self]))
  File "/root/Erps/erp_environnement/lib/python3.10/site-packages/django/template/base.py", line 966, in render_annotated
    return self.render(context)
  File "/root/Erps/erp_environnement/lib/python3.10/site-packages/django/template/loader_tags.py", line 63, in render
    result = block.nodelist.render(context)
  File "/root/Erps/erp_environnement/lib/python3.10/site-packages/django/template/base.py", line 1005, in render
    return SafeString("".join([node.render_annotated(context) for node in self]))
  File "/root/Erps/erp_environnement/lib/python3.10/site-packages/django/template/base.py", line 1005, in <listcomp>
    return SafeString("".join([node.render_annotated(context) for node in self]))
  File "/root/Erps/erp_environnement/lib/python3.10/site-packages/django/template/base.py", line 966, in render_annotated
    return self.render(context)
  File "/root/Erps/erp_environnement/lib/python3.10/site-packages/django/template/defaulttags.py", line 238, in render
    nodelist.append(node.render_annotated(context))
  File "/root/Erps/erp_environnement/lib/python3.10/site-packages/django/template/base.py", line 966, in render_annotated
    return self.render(context)
  File "/root/Erps/erp_environnement/lib/python3.10/site-packages/django/template/base.py", line 1064, in render
    output = self.filter_expression.resolve(context)
  File "/root/Erps/erp_environnement/lib/python3.10/site-packages/django/template/base.py", line 715, in resolve
    obj = self.var.resolve(context)
  File "/root/Erps/erp_environnement/lib/python3.10/site-packages/django/template/base.py", line 847, in resolve
    value = self._resolve_lookup(context)
  File "/root/Erps/erp_environnement/lib/python3.10/site-packages/django/template/base.py", line 890, in _resolve_lookup
    current = getattr(current, bit)
  File "/root/Erps/erpfinal/erp/tiers/models.py", line 194, in remaining_amount
    return round(self.total_amount + self.solde - (self.total_paid_amount + self.total_rembourse + self.total_annule),0)
  File "/root/Erps/erpfinal/erp/tiers/models.py", line 179, in total_amount
    return sum(Decimal(bon.get_total_soldprice) for bon in self.client_bonS.exclude(idBon__startswith='BECH'))
  File "/root/Erps/erpfinal/erp/tiers/models.py", line 179, in <genexpr>
    return sum(Decimal(bon.get_total_soldprice) for bon in self.client_bonS.exclude(idBon__startswith='BECH'))
  File "/root/Erps/erpfinal/erp/ventes/models.py", line 174, in get_total_soldprice
    price_part = self.produits_en_bon_sorties.aggregate(total_price=Sum('totalprice'))['total_price']
  File "/root/Erps/erp_environnement/lib/python3.10/site-packages/django/db/models/manager.py", line 87, in manager_method
    return getattr(self.get_queryset(), name)(*args, **kwargs)
  File "/root/Erps/erp_environnement/lib/python3.10/site-packages/django/db/models/query.py", line 592, in aggregate
    return self.query.chain().get_aggregation(self.db, kwargs)
  File "/root/Erps/erp_environnement/lib/python3.10/site-packages/django/db/models/sql/query.py", line 554, in get_aggregation
    result = compiler.execute_sql(SINGLE)
  File "/root/Erps/erp_environnement/lib/python3.10/site-packages/django/db/models/sql/compiler.py", line 1562, in execute_sql
    cursor.execute(sql, params)
  File "/root/Erps/erp_environnement/lib/python3.10/site-packages/django/db/backends/utils.py", line 102, in execute
    return super().execute(sql, params)
  File "/root/Erps/erp_environnement/lib/python3.10/site-packages/django/db/backends/utils.py", line 67, in execute
    return self._execute_with_wrappers(
  File "/root/Erps/erp_environnement/lib/python3.10/site-packages/django/db/backends/utils.py", line 80, in _execute_with_wrappers
    return executor(sql, params, many, context)
  File "/root/Erps/erp_environnement/lib/python3.10/site-packages/django/db/backends/utils.py", line 84, in _execute
    with self.db.wrap_database_errors:
  File "/root/Erps/erp_environnement/lib/python3.10/site-packages/django/db/utils.py", line 91, in __exit__
    raise dj_exc_value.with_traceback(traceback) from exc_value
  File "/root/Erps/erp_environnement/lib/python3.10/site-packages/django/db/backends/utils.py", line 89, in _execute
    return self.cursor.execute(sql, params)
  File "/root/Erps/erp_environnement/lib/python3.10/site-packages/django/db/backends/sqlite3/base.py", line 328, in execute
    return super().execute(query, params)
django.db.utils.OperationalError: database is locked
Not Found: /favicon.ico
/root/Erps/erp_environnement/lib/python3.10/site-packages/django/db/models/fields/__init__.py:1595: RuntimeWarning: DateTimeField BonTransport.date_depart received a naive datetime (2024-08-29 00:00:00) while time zone support is active.
  warnings.warn(
/root/Erps/erp_environnement/lib/python3.10/site-packages/django/db/models/fields/__init__.py:1595: RuntimeWarning: DateTimeField CourseLivraison.dateTimeAffectation received a naive datetime (2024-08-29 13:42:17.102540) while time zone support is active.
  warnings.warn(
Internal Server Error: /reglements/reglements
Traceback (most recent call last):
  File "/root/Erps/erp_environnement/lib/python3.10/site-packages/django/db/backends/base/base.py", line 313, in _commit
    return self.connection.commit()
sqlite3.OperationalError: database is locked

The above exception was the direct cause of the following exception:

Traceback (most recent call last):
  File "/root/Erps/erp_environnement/lib/python3.10/site-packages/django/core/handlers/exception.py", line 55, in inner
    response = get_response(request)
  File "/root/Erps/erpfinal/erp/users/middleware.py", line 14, in __call__
    myuser.save()
  File "/root/Erps/erpfinal/erp/users/models.py", line 22, in save
    super(CustomUser, self).save(*args, **kwargs)
  File "/root/Erps/erp_environnement/lib/python3.10/site-packages/django/contrib/auth/base_user.py", line 76, in save
    super().save(*args, **kwargs)
  File "/root/Erps/erp_environnement/lib/python3.10/site-packages/django/db/models/base.py", line 814, in save
    self.save_base(
  File "/root/Erps/erp_environnement/lib/python3.10/site-packages/django/db/models/base.py", line 873, in save_base
    with context_manager:
  File "/root/Erps/erp_environnement/lib/python3.10/site-packages/django/db/transaction.py", line 263, in __exit__
    connection.commit()
  File "/root/Erps/erp_environnement/lib/python3.10/site-packages/django/utils/asyncio.py", line 26, in inner
    return func(*args, **kwargs)
  File "/root/Erps/erp_environnement/lib/python3.10/site-packages/django/db/backends/base/base.py", line 337, in commit
    self._commit()
  File "/root/Erps/erp_environnement/lib/python3.10/site-packages/django/db/backends/base/base.py", line 312, in _commit
    with debug_transaction(self, "COMMIT"), self.wrap_database_errors:
  File "/root/Erps/erp_environnement/lib/python3.10/site-packages/django/db/utils.py", line 91, in __exit__
    raise dj_exc_value.with_traceback(traceback) from exc_value
  File "/root/Erps/erp_environnement/lib/python3.10/site-packages/django/db/backends/base/base.py", line 313, in _commit
    return self.connection.commit()
django.db.utils.OperationalError: database is locked
Not Found: /favicon.ico
Not Found: /media/media/document/WhatsApp_Image_2024-08-19_à_15.26.28_9ba2b4d0_jbOvKD4.jpg
Not Found: /favicon.ico
Not Found: /cpsess8138755743/scripts12/terminal/
Internal Server Error: /FD873AC4-CF86-4FED-84EC-4BD59C6F17A7
Traceback (most recent call last):
  File "/root/Erps/erp_environnement/lib/python3.10/site-packages/django/core/handlers/exception.py", line 55, in inner
    response = get_response(request)
  File "/root/Erps/erp_environnement/lib/python3.10/site-packages/django/utils/deprecation.py", line 136, in __call__
    response = self.process_response(request, response)
  File "/root/Erps/erp_environnement/lib/python3.10/site-packages/django/middleware/common.py", line 108, in process_response
    return self.response_redirect_class(self.get_full_path_with_slash(request))
  File "/root/Erps/erp_environnement/lib/python3.10/site-packages/django/middleware/common.py", line 87, in get_full_path_with_slash
    raise RuntimeError(
RuntimeError: You called this URL via POST, but the URL doesn't end in a slash and you have APPEND_SLASH set. Django can't redirect to the slash URL while maintaining POST data. Change your form to point to 38.242.243.169/FD873AC4-CF86-4FED-84EC-4BD59C6F17A7/ (note the trailing slash), or set APPEND_SLASH=False in your Django settings.
/root/Erps/erp_environnement/lib/python3.10/site-packages/django/db/models/fields/__init__.py:1595: RuntimeWarning: DateTimeField ConfirmationBl.dateConfirmation received a naive datetime (2024-08-29 14:51:04.543032) while time zone support is active.
  warnings.warn(
/root/Erps/erp_environnement/lib/python3.10/site-packages/django/db/models/fields/__init__.py:1595: RuntimeWarning: DateTimeField ConfirmationBl.dateConfirmation received a naive datetime (2024-08-29 14:51:46.061226) while time zone support is active.
  warnings.warn(
/root/Erps/erp_environnement/lib/python3.10/site-packages/django/db/models/fields/__init__.py:1595: RuntimeWarning: DateTimeField ConfirmationBl.dateConfirmation received a naive datetime (2024-08-29 14:57:53.150269) while time zone support is active.
  warnings.warn(
Not Found: /robots.txt
/root/Erps/erp_environnement/lib/python3.10/site-packages/django/db/models/fields/__init__.py:1595: RuntimeWarning: DateTimeField CourseLivraison.dateTimeAffectation received a naive datetime (2024-08-29 15:06:29.687431) while time zone support is active.
  warnings.warn(
/root/Erps/erp_environnement/lib/python3.10/site-packages/django/db/models/fields/__init__.py:1595: RuntimeWarning: DateTimeField BonTransport.date_depart received a naive datetime (2024-08-29 00:00:00) while time zone support is active.
  warnings.warn(
Not Found: /actuator/gateway/routes/
/root/Erps/erp_environnement/lib/python3.10/site-packages/django/db/models/fields/__init__.py:1595: RuntimeWarning: DateTimeField CourseLivraison.dateTimeAffectation received a naive datetime (2024-08-29 15:14:14.532111) while time zone support is active.
  warnings.warn(
/root/Erps/erp_environnement/lib/python3.10/site-packages/django/db/models/fields/__init__.py:1595: RuntimeWarning: DateTimeField ConfirmationBl.dateConfirmation received a naive datetime (2024-08-29 15:18:59.218126) while time zone support is active.
  warnings.warn(
Internal Server Error: /get_sales/
Traceback (most recent call last):
  File "/root/Erps/erp_environnement/lib/python3.10/site-packages/django/db/backends/base/base.py", line 313, in _commit
    return self.connection.commit()
sqlite3.OperationalError: database is locked

The above exception was the direct cause of the following exception:

Traceback (most recent call last):
  File "/root/Erps/erp_environnement/lib/python3.10/site-packages/django/core/handlers/exception.py", line 55, in inner
    response = get_response(request)
  File "/root/Erps/erpfinal/erp/users/middleware.py", line 14, in __call__
    myuser.save()
  File "/root/Erps/erpfinal/erp/users/models.py", line 22, in save
    super(CustomUser, self).save(*args, **kwargs)
  File "/root/Erps/erp_environnement/lib/python3.10/site-packages/django/contrib/auth/base_user.py", line 76, in save
    super().save(*args, **kwargs)
  File "/root/Erps/erp_environnement/lib/python3.10/site-packages/django/db/models/base.py", line 814, in save
    self.save_base(
  File "/root/Erps/erp_environnement/lib/python3.10/site-packages/django/db/models/base.py", line 873, in save_base
    with context_manager:
  File "/root/Erps/erp_environnement/lib/python3.10/site-packages/django/db/transaction.py", line 263, in __exit__
    connection.commit()
  File "/root/Erps/erp_environnement/lib/python3.10/site-packages/django/utils/asyncio.py", line 26, in inner
    return func(*args, **kwargs)
  File "/root/Erps/erp_environnement/lib/python3.10/site-packages/django/db/backends/base/base.py", line 337, in commit
    self._commit()
  File "/root/Erps/erp_environnement/lib/python3.10/site-packages/django/db/backends/base/base.py", line 312, in _commit
    with debug_transaction(self, "COMMIT"), self.wrap_database_errors:
  File "/root/Erps/erp_environnement/lib/python3.10/site-packages/django/db/utils.py", line 91, in __exit__
    raise dj_exc_value.with_traceback(traceback) from exc_value
  File "/root/Erps/erp_environnement/lib/python3.10/site-packages/django/db/backends/base/base.py", line 313, in _commit
    return self.connection.commit()
django.db.utils.OperationalError: database is locked
Internal Server Error: /get_sales/
Traceback (most recent call last):
  File "/root/Erps/erp_environnement/lib/python3.10/site-packages/django/db/backends/utils.py", line 89, in _execute
    return self.cursor.execute(sql, params)
  File "/root/Erps/erp_environnement/lib/python3.10/site-packages/django/db/backends/sqlite3/base.py", line 328, in execute
    return super().execute(query, params)
sqlite3.OperationalError: database is locked

The above exception was the direct cause of the following exception:

Traceback (most recent call last):
  File "/root/Erps/erp_environnement/lib/python3.10/site-packages/django/core/handlers/exception.py", line 55, in inner
    response = get_response(request)
  File "/root/Erps/erp_environnement/lib/python3.10/site-packages/django/core/handlers/base.py", line 197, in _get_response
    response = wrapped_callback(request, *callback_args, **callback_kwargs)
  File "/root/Erps/erpfinal/erp/inventory/views.py", line 101, in get_sales
    if len(bill.bon_garantie.all()) == 0 and len(bill.MesbonRetours.all()) == 0 and len(bill.produits_en_bon_sorties.all()) > 0:
  File "/root/Erps/erp_environnement/lib/python3.10/site-packages/django/db/models/query.py", line 380, in __len__
    self._fetch_all()
  File "/root/Erps/erp_environnement/lib/python3.10/site-packages/django/db/models/query.py", line 1881, in _fetch_all
    self._result_cache = list(self._iterable_class(self))
  File "/root/Erps/erp_environnement/lib/python3.10/site-packages/django/db/models/query.py", line 91, in __iter__
    results = compiler.execute_sql(
  File "/root/Erps/erp_environnement/lib/python3.10/site-packages/django/db/models/sql/compiler.py", line 1562, in execute_sql
    cursor.execute(sql, params)
  File "/root/Erps/erp_environnement/lib/python3.10/site-packages/django/db/backends/utils.py", line 102, in execute
    return super().execute(sql, params)
  File "/root/Erps/erp_environnement/lib/python3.10/site-packages/django/db/backends/utils.py", line 67, in execute
    return self._execute_with_wrappers(
  File "/root/Erps/erp_environnement/lib/python3.10/site-packages/django/db/backends/utils.py", line 80, in _execute_with_wrappers
    return executor(sql, params, many, context)
  File "/root/Erps/erp_environnement/lib/python3.10/site-packages/django/db/backends/utils.py", line 84, in _execute
    with self.db.wrap_database_errors:
  File "/root/Erps/erp_environnement/lib/python3.10/site-packages/django/db/utils.py", line 91, in __exit__
    raise dj_exc_value.with_traceback(traceback) from exc_value
  File "/root/Erps/erp_environnement/lib/python3.10/site-packages/django/db/backends/utils.py", line 89, in _execute
    return self.cursor.execute(sql, params)
  File "/root/Erps/erp_environnement/lib/python3.10/site-packages/django/db/backends/sqlite3/base.py", line 328, in execute
    return super().execute(query, params)
django.db.utils.OperationalError: database is locked
